Workbook
Name _1_year: #REF!
Name _1_yr_after_compl_yr: #REF!
Name _1_yr_after_compl_yr0: #REF!
Name _1_yr_before_compl_yr: #REF!
Name _2_2010_Output_Pechan_Utility_Boiler: #REF!
Name _2_year: #REF!
Name _2_year_after_compl_yr: #REF!
Name _2_years: #REF!
Name _2_yrs_before_compl_yr: #REF!
Name _20_years: #REF!
Name _2003_to_2005_inflator: #REF!
Name _22_years: #REF!
Name _25_years: #REF!
Name _3_years: #REF!
Name _3_yrs_before_compl_yr: #REF!
Name _30_years: #REF!
Name _5_years: #REF!
Name _5_yrs_after_compl_yr: #REF!
Name _d2: '[1]County-to-Node'!$A$3:$C$2624
Name AEO2013ER_NEL: '[2]AEO 2017 without CPP M'!$A$5:$AR$27
Name AEOCosts: #REF!
Name ALBA2007: '[3]Supply Data'!$B$2:$J$2300
Name Alberta: #REF!
Name ALLOWPRICE: #REF!
Name analysis_year: #REF!
Name annualavg: '[4]AnnualAvg 2003$ per MMBtu'!$A$2:$W$85
Name asdfasdf: #REF!
Name CAIR_Share: #REF!
Name CAIR_State: #REF!
Name CAN_DR: '[5]Regions-CCOST Scalar'!#REF!
Name CanadaWindProfile: '[6]Canada Wind Profile'!$A$1:$Z$133
Name Capacity: [7]Parameters!$C$3
Name Capacity2: [7]Parameters!$C$3
Name capital_20_for_ipm: #REF!
Name capital_22_for_ipm: #REF!
Name capital_25_for_ipm: #REF!
Name capital_30_for_ipm: #REF!
Name capital_ct_30_for_ipm: #REF!
Name CDR: [3]Key!$L$2:$M$194
Name ck_310_Tm_master2: #REF!
Name ck_310_Tm_master2_ICF: #REF!
Name Clear10: #REF!
Name Clear9: #REF!
Name COALPRICE: #REF!
Name CoalRegion: #REF!
Name COALTYPE: '[8]Assumps-CoalTypes'!$A$7:$L$50
Name COALTYPES: '[9]Assumps-CoalTypes'!$A$6:$K$31
Name COALTYPESOLD: #REF!
Name ColumnOffset: '[2]Net Imports for Generation'!#REF!
Name compl_yr: #REF!
Name compl_yr_for_ipm: #REF!
Name compliance_year_1: #REF!
Name compliance_year_2: #REF!
Name compliance_year_3: #REF!
Name compliance_year_4: #REF!
Name compliance_year_5: #REF!
Name compliance_year_6: #REF!
Name compliance_year_7: #REF!
Name compliance_year_8: #REF!
Name compliance_year_9: #REF!

Sheet About
A1: SYTaDOMC Start Year Transmission and Distribution OM Costs | B1: Alabama | C1: 45194 | F1: Alabama | G1: AL
B2: =LOOKUP(B1,F1:G50,G1:G50) -> AL | F2: Alaska | G2: AK
A3: Sources: | B3: Transmission O&M Spending | F3: Arizona | G3: AZ
B4: U.S. Energy Information Administration | F4: Arkansas | G4: AR
B5: 2021 | F5: California | G5: CA
B6: Utilities continue to increase spending on the electric transmission system | F6: Colorado | G6: CO
B7: https://www.eia.gov/todayinenergy/detail.php?id=47316#:~:text=Utilities%20spent%20%2416.6%20billion%20on,7%25%20more%20than%20in%202018.&text=Power%20plants%20are%20often%20located,power%20lines%20to%20deliver%20electricity. | F7: Connecticut | G7: CT
B8: First paragraph | F8: Delaware | G8: DE
F9: Florida | G9: FL
B10: Distribution O&M Spending | F10: Georgia | G10: GA
B11: U.S. Energy Information Administration | F11: Hawaii | G11: HI
B12: 2021 | F12: Idaho | G12: ID
B13: Major utilities' spending on the electric distribution system continues to increase | F13: Illinois | G13: IL
B14: https://www.eia.gov/todayinenergy/detail.php?id=48136#:~:text=Annual%20spending%20on%20electricity%20distribution,2000%20after%20adjusting%20for%20inflation. | F14: Indiana | G14: IN
B15: First paragraph | F15: Iowa | G15: IA
F16: Kansas | G16: KS
B17: National Renewable Energy Laboratory | F17: Kentucky | G17: KY
B18: 2012 | F18: Louisiana | G18: LA
B19: Renewable Energy Futures Study: Volume 1 | F19: Maine | G19: ME
B20: http://www.nrel.gov/docs/fy12osti/52409-1.pdf | F20: Maryland | G20: MD
B21: Page 3-14, Figure 3-8 | F21: Massachusetts | G21: MA
F22: Michigan | G22: MI
B23: HIFLD Open Data Electric Power Transmission Lines | F23: Minnesota | G23: MN
B24: 2020 | F24: Mississippi | G24: MS
B25: https://hifld-geoplatform.opendata.arcgis.com/datasets/electric-power-transmission-lines | F25: Missouri | G25: MO
B26: Analysis done by RMI calculations | F26: Montana | G26: MT
F27: Nebraska | G27: NE
F28: Nevada | G28: NV
A29: Note: | F29: New Hampshire | G29: NH
F30: New Jersey | G30: NJ
A31: We adjust 2021 dollars to 2012 dollars using the following conversion factor: | F31: New Mexico | G31: NM
A32: 0.84730413 | F32: New York | G32: NY
A33: See "cpi.xlsx" in the InputData folder for source information. | F33: North Carolina | G33: NC
F34: North Dakota | G34: ND
F35: Ohio | G35: OH
F36: Oklahoma | G36: OK
F37: Oregon | G37: OR
F38: Pennsylvania | G38: PA
F39: Rhode Island | G39: RI
F40: South Carolina | G40: SC
...

Sheet HIFLD Outputs
A1: Ranking by kvolt*miles | B1: State | C1: Abb | D1: kVolt Miles | E1: Miles | F1: Fraction kV*miles / total
A2: 1 | B2: Texas | C2: TX | D2: 12422854 | E2: 66809.842 | F2: =D2/$D$53 -> 0.084009472
A3: 2 | B3: California | C3: CA | D3: 10672018 | E3: 51067.879 | F3: =D3/$D$53 -> 0.072169455
A4: 3 | B4: Oregon | C4: OR | D4: 5571799 | E4: 20876.781 | F4: =D4/$D$53 -> 0.037679255
A5: 4 | B5: Washington | C5: WA | D5: 5407549.7 | E5: 24875.462 | F5: =D5/$D$53 -> 0.036568521
A6: 5 | B6: Ohio | C6: OH | D6: 4601291.8 | E6: 21215.997 | F6: =D6/$D$53 -> 0.031116207
A7: 6 | B7: Nevada | C7: NV | D7: 4475926.4 | E7: 12414.922 | F7: =D7/$D$53 -> 0.030268424
A8: 7 | B8: Indiana | C8: IN | D8: 4333497.1 | E8: 19235.688 | F8: =D8/$D$53 -> 0.029305247
A9: 8 | B9: Arizona | C9: AZ | D9: 4161224.3 | E9: 15442.246 | F9: =D9/$D$53 -> 0.028140253
A10: 9 | B10: Florida | C10: FL | D10: 3803657.7 | E10: 21123.461 | F10: =D10/$D$53 -> 0.025722211
A11: 10 | B11: Georgia | C11: GA | D11: 3764607.6 | E11: 19550.865 | F11: =D11/$D$53 -> 0.025458135
A12: 11 | B12: New York | C12: NY | D12: 3642095.9 | E12: 22575.592 | F12: =D12/$D$53 -> 0.024629651
A13: 12 | B13: Minnesota | C13: MN | D13: 3603526.7 | E13: 20544.868 | F13: =D13/$D$53 -> 0.024368827
... A51: 50 | B51: Hawaii | C51: HI | D51: 67983.253 | E51: 773.50391 | F51: =D51/$D$53 -> 0.00045973632
A53: Total | D53: =SUM(D2:D51) -> 1.4787444e+08 | F53: =SUM(F1:F51) -> 1

Sheet Data National
A1: BAU transmission capacity in 2010 is given in the figure caption as
A2: 150-200 million MW*miles. The graph shows the additional quantity
A3: of transmission being built in the "baseline" scenario, which extends
A4: to 2050 in the RE Futures Report. We assume the growth is linear
A5: and interpolate.
A7: Unfortunately, data are only available as a graph (not in numbers), so
A8: we must estimate by measuring pixels on the graph.
A10: 2010 Transmission (low estimate): | B10: =150*10^6 -> 150000000 | C10: MW*miles
A11: 2010 Transmission (high estimate): | B11: =200*10^6 -> 200000000 | C11: MW*miles
A12: 2010 Transmission: | B12: =AVERAGE(B10:B11) -> 175000000 | C12: MW*miles
A14: BAU New Transmission
A15: Pixels per 50 million MW*miles: | B15: 141 | C15: pixels
A16: Pixel height of new transmission: | B16: 15 | C16: pixels
A17: New transmission quantity in 2050 | B17: =B16/B15*50*10^6 -> 5319148.9 | C17: MW*miles
A32: National Data
B33: 2010 | C33: 2011 | D33: 2012 | E33: 2013 | F33: 2014 | G33: 2015 | H33: 2016 | I33: 2017 | J33: 2018 | K33: 2019 | L33: 2020 | M33: 2021 | N33: 2022 | O33: 2023 | P33: 2024 | Q33: 2025 | R33: 2026 | S33: 2027 | T33: 2028 | U33: 2029 | V33: 2030 | W33: 2031 | X33: 2032 | Y33: 2033 | Z33: 2034 | AA33: 2035 | AB33: 2036 | AC33: 2037 | AD33: 2038 | AE33: 2039 | AF33: 2040 | AG33: 2041 | AH33: 2042 | AI33: 2043 | AJ33: 2044 | AK33: 2045 | AL33: 2046 | AM33: 2047 | AN33: 2048 | AO33: 2049 | AP33: 2050
A34: BAU Transmission Capacity (MW*miles) | B34: =B12 -> 175000000 | C34: =B34+'Data National'!$B$17/(2050-2010) -> 1.7513298e+08 | D34: =C34+'Data National'!$B$17/(2050-2010) -> 1.7526596e+08 | E34: =D34+'Data National'!$B$17/(2050-2010) -> 1.7539894e+08 | F34: =E34+'Data National'!$B$17/(2050-2010) -> 1.7553191e+08 | G34: =F34+'Data National'!$B$17/(2050-2010) -> 1.7566489e+08 | H34: =G34+'Data National'!$B$17/(2050-2010) -> 1.7579787e+08 | I34: =H34+'Data National'!$B$17/(2050-2010) -> 1.7593085e+08 | J34: =I34+'Data National'!$B$17/(2050-2010) -> 1.7606383e+08 | ... AP34: =AO34+'Data National'!$B$17/(2050-2010) -> 1.8031915e+08
B36: Costs ($)
A37: Transmission Construction | B37: =16600000000*About!A32 -> 1.4065249e+10
A38: Distribution Construction | B38: =14600000000*About!A32 -> 1.237064e+10
A40: State
A41: =About!B1 -> Alabama
A42: BTC | B42: =SUMIFS('HIFLD Outputs'!$F$2:$F$49,'HIFLD Outputs'!$B$2:$B$49,'Data National'!$A$41)*B34 -> 3613517.4 | C42: =SUMIFS('HIFLD Outputs'!$F$2:$F$49,'HIFLD Outputs'!$B$2:$B$49,'Data National'!$A$41)*C34 -> 3616263.3 | D42: =SUMIFS('HIFLD Outputs'!$F$2:$F$49,'HIFLD Outputs'!$B$2:$B$49,'Data National'!$A$41)*D34 -> 3619009.1 | E42: =SUMIFS('HIFLD Outputs'!$F$2:$F$49,'HIFLD Outputs'!$B$2:$B$49,'Data National'!$A$41)*E34 -> 3621754.9 | F42: =SUMIFS('HIFLD Outputs'!$F$2:$F$49,'HIFLD Outputs'!$B$2:$B$49,'Data National'!$A$41)*F34 -> 3624500.8 | G42: =SUMIFS('HIFLD Outputs'!$F$2:$F$49,'HIFLD Outputs'!$B$2:$B$49,'Data National'!$A$41)*G34 -> 3627246.6 | H42: =SUMIFS('HIFLD Outputs'!$F$2:$F$49,'HIFLD Outputs'!$B$2:$B$49,'Data National'!$A$41)*H34 -> 3629992.4 | I42: =SUMIFS('HIFLD Outputs'!$F$2:$F$49,'HIFLD Outputs'!$B$2:$B$49,'Data National'!$A$41)*I34 -> 3632738.3 | ... AP42: =SUMIFS('HIFLD Outputs'!$F$2:$F$49,'HIFLD Outputs'!$B$2:$B$49,'Data National'!$A$41)*AP34 -> 3723350.8
A43: Transmission Construction | B43: =B37*SUMIFS('HIFLD Outputs'!$F$2:$F$49,'HIFLD Outputs'!$B$2:$B$49,'Data National'!$A$41) -> 2.9042869e+08
A44: Distribution Construction | B44: =B38*SUMIFS('HIFLD Outputs'!$F$2:$F$49,'HIFLD Outputs'!$B$2:$B$49,'Data National'!$A$41) -> 2.5543728e+08

Sheet SYTaDOMC-Transmission
B1: Costs ($)
A2: Transmission Construction | B2: ='Data National'!B43 -> 2.9042869e+08

Sheet SYTaDOMC-Distribution
B1: Costs ($)
A2: Transmission Construction | B2: ='Data National'!B44 -> 2.5543728e+08
